Workbook
Name HouseholdMode: Settings!$C$5
Name PersonA: Settings!$C$6
Name PersonB: Settings!$C$7
Name DefaultSplitA: Settings!$C$8
Name Province: Settings!$C$9
Name Configured: Settings!$C$10
Name TransferWindowDays: Settings!$C$11
Name SkipDuplicates: Settings!$C$12
Name Currency: Settings!$C$13
Name AppVersion: Settings!$C$14
Name ReportMonth: Dashboard!$C$6
Name ReportView: Dashboard!$F$6
Name ButtonAnchor: Dashboard!$B$3
Name TxnButtonAnchor: Transactions!$B$3
Name TopMerchants: Dashboard!$B$32:$C$41
Name CoupleBlock: Dashboard!$B$43:$I$53
Name MonthList: Engine!$D$3:$D$38
Name ViewList: Engine!$F$3:$F$5
Name HouseholdOnly: Engine!$F$3
Name OwnerList: Engine!$H$3:$H$5
Name TypeList: Engine!$J$3:$J$6
Name YesNoList: Engine!$L$3:$L$4
Name AccountTypeList: Engine!$N$3:$N$8
Name RuleFieldList: Engine!$P$3:$P$6
Name RuleTestList: Engine!$R$3:$R$8
Name RuleFlowList: Engine!$T$3:$T$5
Name DelimiterList: Engine!$V$3:$V$6
Name AmountModeList: Engine!$X$3:$X$5
Name DateFormatList: Engine!$Z$3:$Z$9
Name ProvinceList: Engine!$AB$3:$AB$15
Name LedgerRows: Engine!$AD$3
Name TaxTagList: Engine!$AF$3:$AF$17
Name GroupList: Engine!$AH$3:$AH$16
Name TaxYear: 'Tax Summary'!$C$3
Name CategoryList: =tblCategories[Category]
Name AccountList: =tblAccounts[Account]

Sheet Dashboard
B1: Canadian Finance Tracker
B2: Type your transactions on the Transactions sheet, then read your month here. Everything stays in this file - nothing is uploaded.
B6: Report month | C6: 2026-08 | E6: View | F6: Household | H6: Needs a category | I6: =COUNTIF(tblTxn[Category],"Uncategorized")
B8: This month at a glance
B9: Money in | C9: =SUMIFS(tblTxn[View Amount],tblTxn[Month],ReportMonth,tblTxn[Type],"Income") | E9: Essential spending | F9: =-SUMIFS(tblTxn[View Amount],tblTxn[Month],ReportMonth,tblTxn[Type],"Expense",tblTxn[Essential],"Yes") | H9: Uncategorized rows distort every number on this page. Filter the Transactions sheet to them and pick a category from the drop-down.
B10: Money out | C10: =-SUMIFS(tblTxn[View Amount],tblTxn[Month],ReportMonth,tblTxn[Type],"Expense") | E10: Discretionary spending | F10: =C10-F9
B11: Saved & invested | C11: =-SUMIFS(tblTxn[View Amount],tblTxn[Month],ReportMonth,tblTxn[Type],"Saving") | E11: Average spend per day | F11: =IFERROR(C10/DAY(EOMONTH(DATE(VALUE(LEFT(ReportMonth,4)),VALUE(RIGHT(ReportMonth,2)),1),0)),"")
B12: Net cash flow | C12: =C9-C10-C11 | E12: Transactions this month | F12: =COUNTIFS(tblTxn[Month],ReportMonth)
B13: Savings rate | C13: =IFERROR((C9-C10)/C9,"") | E13: Left in monthly budget | F13: =IF(SUM(tblCategories[Monthly Budget])=0,"",SUM(tblCategories[Monthly Budget])-C10)
B15: Where the money went
B16: Group | C16: This month | E16: 12-month average
B17: Housing | C17: =-SUMIFS(tblTxn[View Amount],tblTxn[Month],ReportMonth,tblTxn[Group],$B17) | E17: =-SUMIFS(tblTxn[View Amount],tblTxn[Group],$B17,tblTxn[Month],">="&TEXT(EDATE(DATE(VALUE(LEFT(ReportMonth,4)),VALUE(RIGHT(ReportMonth,2)),1),-11),"yyyy-mm"),tblTxn[Month],"<="&ReportMonth)/12
B18: Utilities | C18: =-SUMIFS(tblTxn[View Amount],tblTxn[Month],ReportMonth,tblTxn[Group],$B18) | E18: =-SUMIFS(tblTxn[View Amount],tblTxn[Group],$B18,tblTxn[Month],">="&TEXT(EDATE(DATE(VALUE(LEFT(ReportMonth,4)),VALUE(RIGHT(ReportMonth,2)),1),-11),"yyyy-mm"),tblTxn[Month],"<="&ReportMonth)/12
B19: Food | C19: =-SUMIFS(tblTxn[View Amount],tblTxn[Month],ReportMonth,tblTxn[Group],$B19) | E19: =-SUMIFS(tblTxn[View Amount],tblTxn[Group],$B19,tblTxn[Month],">="&TEXT(EDATE(DATE(VALUE(LEFT(ReportMonth,4)),VALUE(RIGHT(ReportMonth,2)),1),-11),"yyyy-mm"),tblTxn[Month],"<="&ReportMonth)/12
B20: Transportation | C20: =-SUMIFS(tblTxn[View Amount],tblTxn[Month],ReportMonth,tblTxn[Group],$B20) | E20: =-SUMIFS(tblTxn[View Amount],tblTxn[Group],$B20,tblTxn[Month],">="&TEXT(EDATE(DATE(VALUE(LEFT(ReportMonth,4)),VALUE(RIGHT(ReportMonth,2)),1),-11),"yyyy-mm"),tblTxn[Month],"<="&ReportMonth)/12
B21: Health | C21: =-SUMIFS(tblTxn[View Amount],tblTxn[Month],ReportMonth,tblTxn[Group],$B21) | E21: =-SUMIFS(tblTxn[View Amount],tblTxn[Group],$B21,tblTxn[Month],">="&TEXT(EDATE(DATE(VALUE(LEFT(ReportMonth,4)),VALUE(RIGHT(ReportMonth,2)),1),-11),"yyyy-mm"),tblTxn[Month],"<="&ReportMonth)/12
B22: Family | C22: =-SUMIFS(tblTxn[View Amount],tblTxn[Month],ReportMonth,tblTxn[Group],$B22) | E22: =-SUMIFS(tblTxn[View Amount],tblTxn[Group],$B22,tblTxn[Month],">="&TEXT(EDATE(DATE(VALUE(LEFT(ReportMonth,4)),VALUE(RIGHT(ReportMonth,2)),1),-11),"yyyy-mm"),tblTxn[Month],"<="&ReportMonth)/12
B23: Education | C23: =-SUMIFS(tblTxn[View Amount],tblTxn[Month],ReportMonth,tblTxn[Group],$B23) | E23: =-SUMIFS(tblTxn[View Amount],tblTxn[Group],$B23,tblTxn[Month],">="&TEXT(EDATE(DATE(VALUE(LEFT(ReportMonth,4)),VALUE(RIGHT(ReportMonth,2)),1),-11),"yyyy-mm"),tblTxn[Month],"<="&ReportMonth)/12
B24: Personal | C24: =-SUMIFS(tblTxn[View Amount],tblTxn[Month],ReportMonth,tblTxn[Group],$B24) | E24: =-SUMIFS(tblTxn[View Amount],tblTxn[Group],$B24,tblTxn[Month],">="&TEXT(EDATE(DATE(VALUE(LEFT(ReportMonth,4)),VALUE(RIGHT(ReportMonth,2)),1),-11),"yyyy-mm"),tblTxn[Month],"<="&ReportMonth)/12
B25: Travel | C25: =-SUMIFS(tblTxn[View Amount],tblTxn[Month],ReportMonth,tblTxn[Group],$B25) | E25: =-SUMIFS(tblTxn[View Amount],tblTxn[Group],$B25,tblTxn[Month],">="&TEXT(EDATE(DATE(VALUE(LEFT(ReportMonth,4)),VALUE(RIGHT(ReportMonth,2)),1),-11),"yyyy-mm"),tblTxn[Month],"<="&ReportMonth)/12
B26: Financial | C26: =-SUMIFS(tblTxn[View Amount],tblTxn[Month],ReportMonth,tblTxn[Group],$B26) | E26: =-SUMIFS(tblTxn[View Amount],tblTxn[Group],$B26,tblTxn[Month],">="&TEXT(EDATE(DATE(VALUE(LEFT(ReportMonth,4)),VALUE(RIGHT(ReportMonth,2)),1),-11),"yyyy-mm"),tblTxn[Month],"<="&ReportMonth)/12
B27: Saving | C27: =-SUMIFS(tblTxn[View Amount],tblTxn[Month],ReportMonth,tblTxn[Group],$B27) | E27: =-SUMIFS(tblTxn[View Amount],tblTxn[Group],$B27,tblTxn[Month],">="&TEXT(EDATE(DATE(VALUE(LEFT(ReportMonth,4)),VALUE(RIGHT(ReportMonth,2)),1),-11),"yyyy-mm"),tblTxn[Month],"<="&ReportMonth)/12
B28: Other | C28: =-SUMIFS(tblTxn[View Amount],tblTxn[Month],ReportMonth,tblTxn[Group],$B28) | E28: =-SUMIFS(tblTxn[View Amount],tblTxn[Group],$B28,tblTxn[Month],">="&TEXT(EDATE(DATE(VALUE(LEFT(ReportMonth,4)),VALUE(RIGHT(ReportMonth,2)),1),-11),"yyyy-mm"),tblTxn[Month],"<="&ReportMonth)/12
B30: Biggest categories this month
B31: Category | C31: Spent or saved | E31: Share of the month
B32: =IFERROR(IF(LARGE(Reports!$Q$29:$Q$148,1)<0,"",INDEX(Reports!$B$29:$B$148,MATCH(LARGE(Reports!$Q$29:$Q$148,1),Reports!$Q$29:$Q$148,0))),"") | C32: =IFERROR(IF(LARGE(Reports!$Q$29:$Q$148,1)<0,"",INDEX(Reports!$N$29:$N$148,MATCH(LARGE(Reports!$Q$29:$Q$148,1),Reports!$Q$29:$Q$148,0))),"") | E32: =IFERROR(IF(C32="","",C32/(C10+C11)),"") | H32: Spending and saving categories, ranked. The share is of everything that left this month: money out plus money saved.
B33: =IFERROR(IF(LARGE(Reports!$Q$29:$Q$148,2)<0,"",INDEX(Reports!$B$29:$B$148,MATCH(LARGE(Reports!$Q$29:$Q$148,2),Reports!$Q$29:$Q$148,0))),"") | C33: =IFERROR(IF(LARGE(Reports!$Q$29:$Q$148,2)<0,"",INDEX(Reports!$N$29:$N$148,MATCH(LARGE(Reports!$Q$29:$Q$148,2),Reports!$Q$29:$Q$148,0))),"") | E33: =IFERROR(IF(C33="","",C33/(C10+C11)),"")
B34: =IFERROR(IF(LARGE(Reports!$Q$29:$Q$148,3)<0,"",INDEX(Reports!$B$29:$B$148,MATCH(LARGE(Reports!$Q$29:$Q$148,3),Reports!$Q$29:$Q$148,0))),"") | C34: =IFERROR(IF(LARGE(Reports!$Q$29:$Q$148,3)<0,"",INDEX(Reports!$N$29:$N$148,MATCH(LARGE(Reports!$Q$29:$Q$148,3),Reports!$Q$29:$Q$148,0))),"") | E34: =IFERROR(IF(C34="","",C34/(C10+C11)),"")
B35: =IFERROR(IF(LARGE(Reports!$Q$29:$Q$148,4)<0,"",INDEX(Reports!$B$29:$B$148,MATCH(LARGE(Reports!$Q$29:$Q$148,4),Reports!$Q$29:$Q$148,0))),"") | C35: =IFERROR(IF(LARGE(Reports!$Q$29:$Q$148,4)<0,"",INDEX(Reports!$N$29:$N$148,MATCH(LARGE(Reports!$Q$29:$Q$148,4),Reports!$Q$29:$Q$148,0))),"") | E35: =IFERROR(IF(C35="","",C35/(C10+C11)),"")
B36: =IFERROR(IF(LARGE(Reports!$Q$29:$Q$148,5)<0,"",INDEX(Reports!$B$29:$B$148,MATCH(LARGE(Reports!$Q$29:$Q$148,5),Reports!$Q$29:$Q$148,0))),"") | C36: =IFERROR(IF(LARGE(Reports!$Q$29:$Q$148,5)<0,"",INDEX(Reports!$N$29:$N$148,MATCH(LARGE(Reports!$Q$29:$Q$148,5),Reports!$Q$29:$Q$148,0))),"") | E36: =IFERROR(IF(C36="","",C36/(C10+C11)),"")
B37: =IFERROR(IF(LARGE(Reports!$Q$29:$Q$148,6)<0,"",INDEX(Reports!$B$29:$B$148,MATCH(LARGE(Reports!$Q$29:$Q$148,6),Reports!$Q$29:$Q$148,0))),"") | C37: =IFERROR(IF(LARGE(Reports!$Q$29:$Q$148,6)<0,"",INDEX(Reports!$N$29:$N$148,MATCH(LARGE(Reports!$Q$29:$Q$148,6),Reports!$Q$29:$Q$148,0))),"") | E37: =IFERROR(IF(C37="","",C37/(C10+C11)),"")
B38: =IFERROR(IF(LARGE(Reports!$Q$29:$Q$148,7)<0,"",INDEX(Reports!$B$29:$B$148,MATCH(LARGE(Reports!$Q$29:$Q$148,7),Reports!$Q$29:$Q$148,0))),"") | C38: =IFERROR(IF(LARGE(Reports!$Q$29:$Q$148,7)<0,"",INDEX(Reports!$N$29:$N$148,MATCH(LARGE(Reports!$Q$29:$Q$148,7),Reports!$Q$29:$Q$148,0))),"") | E38: =IFERROR(IF(C38="","",C38/(C10+C11)),"")
B39: =IFERROR(IF(LARGE(Reports!$Q$29:$Q$148,8)<0,"",INDEX(Reports!$B$29:$B$148,MATCH(LARGE(Reports!$Q$29:$Q$148,8),Reports!$Q$29:$Q$148,0))),"") | C39: =IFERROR(IF(LARGE(Reports!$Q$29:$Q$148,8)<0,"",INDEX(Reports!$N$29:$N$148,MATCH(LARGE(Reports!$Q$29:$Q$148,8),Reports!$Q$29:$Q$148,0))),"") | E39: =IFERROR(IF(C39="","",C39/(C10+C11)),"")
B40: =IFERROR(IF(LARGE(Reports!$Q$29:$Q$148,9)<0,"",INDEX(Reports!$B$29:$B$148,MATCH(LARGE(Reports!$Q$29:$Q$148,9),Reports!$Q$29:$Q$148,0))),"") | C40: =IFERROR(IF(LARGE(Reports!$Q$29:$Q$148,9)<0,"",INDEX(Reports!$N$29:$N$148,MATCH(LARGE(Reports!$Q$29:$Q$148,9),Reports!$Q$29:$Q$148,0))),"") | E40: =IFERROR(IF(C40="","",C40/(C10+C11)),"")
B41: =IFERROR(IF(LARGE(Reports!$Q$29:$Q$148,10)<0,"",INDEX(Reports!$B$29:$B$148,MATCH(LARGE(Reports!$Q$29:$Q$148,10),Reports!$Q$29:$Q$148,0))),"") | C41: =IFERROR(IF(LARGE(Reports!$Q$29:$Q$148,10)<0,"",INDEX(Reports!$N$29:$N$148,MATCH(LARGE(Reports!$Q$29:$Q$148,10),Reports!$Q$29:$Q$148,0))),"") | E41: =IFERROR(IF(C41="","",C41/(C10+C11)),"")
B43: Couple view (selected month)
C44: =PersonA | E44: =PersonB
B45: Paid from own accounts | C45: =-SUMIFS(tblTxn[Amount],tblTxn[Month],ReportMonth,tblTxn[Type],"Expense",tblTxn[Paid By],PersonA) | E45: =-SUMIFS(tblTxn[Amount],tblTxn[Month],ReportMonth,tblTxn[Type],"Expense",tblTxn[Paid By],PersonB)
B46: Fair share of that spending | C46: =-(SUMIFS(tblTxn[Share A],tblTxn[Month],ReportMonth,tblTxn[Type],"Expense",tblTxn[Paid By],PersonA)+SUMIFS(tblTxn[Share A],tblTxn[Month],ReportMonth,tblTxn[Type],"Expense",tblTxn[Paid By],PersonB)) | E46: =-(SUMIFS(tblTxn[Share B],tblTxn[Month],ReportMonth,tblTxn[Type],"Expense",tblTxn[Paid By],PersonA)+SUMIFS(tblTxn[Share B],tblTxn[Month],ReportMonth,tblTxn[Type],"Expense",tblTxn[Paid By],PersonB))
B47: Balance (paid minus share) | C47: =C45-C46 | E47: =E45-E46
...

Sheet Transactions
B1: Transactions
B2: One row per transaction. Money out is negative, money in is positive. Type the Date, Account, Description and Amount; everything else fills itself in, and can be typed over.
B6: Txn ID | C6: Date | D6: Month | E6: Account | F6: Paid By | G6: Owner | H6: Description | I6: Merchant | J6: Amount | K6: Category | L6: Group | M6: Type | N6: Essential | O6: Tax Tag | P6: Split A % | Q6: Share A | R6: Share B | S6: Reimbursable | T6: Notes | U6: Source File | V6: Batch | W6: Match Key | X6: Tagged By | Y6: View Amount
B7: =IF($C7="","","T"&TEXT(ROW()-ROW(tblTxn[[#Headers],[Txn ID]]),"000000")) | C7: 46082 | D7: =IF($C7="","",TEXT($C7,"yyyy-mm")) | E7: BMO Joint Chequing | F7: =IF($C7="","",IFERROR(INDEX(tblAccounts[Owner],MATCH($E7,tblAccounts[Account],0)),"Joint")) | G7: =IF($C7="","",IF(HouseholdMode="Couple",IFERROR(IF(INDEX(tblCategories[Default Owner],MATCH($K7,tblCategories[Category],0))="",$F7,INDEX(tblCategories[Default Owner],MATCH($K7,tblCategories[Category],0))),$F7),$F7)) | H7: RENT PAYMENT 84 BROADVIEW AVE | I7: =IF($H7="","",$H7) | J7: -2350 | K7: =IF($H7="","",IFERROR(INDEX(tblRules[Category],SUMPRODUCT(MIN((1-((tblRules[Enabled]<>"No")*(tblRules[Pattern]<>"")*(tblRules[Category]<>"")*((tblRules[Flow]="Any")+(tblRules[Flow]="")+((tblRules[Flow]="Money out")*($J7<0))+((tblRules[Flow]="Money in")*($J7>0)))*(((tblRules[Look In]="Account")*ISNUMBER(SEARCH(tblRules[Pattern],$E7)))+((tblRules[Look In]<>"Account")*(((tblRules[Test]="Word")*ISNUMBER(SEARCH(" "&tblRules[Pattern]&" "," "&$H7&" ")))+((tblRules[Test]<>"Word")*ISNUMBER(SEARCH(tblRules[Pattern],$H7))))))>0))*1E+9+ROW(tblRules[Pattern])))-ROW(tblRules[[#Headers],[Pattern]])),"Uncategorized")) | L7: =IF($C7="","",IFERROR(INDEX(tblCategories[Group],MATCH($K7,tblCategories[Category],0)),"Other")) | M7: =IF($C7="","",IFERROR(INDEX(tblCategories[Type],MATCH($K7,tblCategories[Category],0)),IF($J7>0,"Income","Expense"))) | N7: =IF($C7="","",IFERROR(INDEX(tblCategories[Essential],MATCH($K7,tblCategories[Category],0)),"No")) | O7: =IF($C7="","",IFERROR(INDEX(tblCategories[Tax Tag],MATCH($K7,tblCategories[Category],0)),"")) | P7: =IF($C7="","",IF($G7=PersonA,1,IF($G7=PersonB,0,IFERROR(INDEX(tblCategories[Joint Split A],MATCH($K7,tblCategories[Category],0)),DefaultSplitA)))) | Q7: =IF($C7="","",ROUND($J7*N($P7),2)) | R7: =IF($C7="","",ROUND($J7-N($Q7),2)) | U7: sample-data | V7: SAMPLE | W7: 9C39F83E | X7: =IF($C7="","",IFERROR(IF(_xlfn.ISFORMULA($K7),"Rule","Manual"),"")) | Y7: =IF($C7="","",IF(ReportView=PersonA,N($Q7),IF(ReportView=PersonB,N($R7),$J7)))
B8: =IF($C8="","","T"&TEXT(ROW()-ROW(tblTxn[[#Headers],[Txn ID]]),"000000")) | C8: 46084 | D8: =IF($C8="","",TEXT($C8,"yyyy-mm")) | E8: Amex Cobalt (Joint) | F8: =IF($C8="","",IFERROR(INDEX(tblAccounts[Owner],MATCH($E8,tblAccounts[Account],0)),"Joint")) | G8: =IF($C8="","",IF(HouseholdMode="Couple",IFERROR(IF(INDEX(tblCategories[Default Owner],MATCH($K8,tblCategories[Category],0))="",$F8,INDEX(tblCategories[Default Owner],MATCH($K8,tblCategories[Category],0))),$F8),$F8)) | H8: IDP PURCHASE - 4612 CANADIAN TIRE #2196 ON | I8: =IF($H8="","",$H8) | J8: -97.88 | K8: =IF($H8="","",IFERROR(INDEX(tblRules[Category],SUMPRODUCT(MIN((1-((tblRules[Enabled]<>"No")*(tblRules[Pattern]<>"")*(tblRules[Category]<>"")*((tblRules[Flow]="Any")+(tblRules[Flow]="")+((tblRules[Flow]="Money out")*($J8<0))+((tblRules[Flow]="Money in")*($J8>0)))*(((tblRules[Look In]="Account")*ISNUMBER(SEARCH(tblRules[Pattern],$E8)))+((tblRules[Look In]<>"Account")*(((tblRules[Test]="Word")*ISNUMBER(SEARCH(" "&tblRules[Pattern]&" "," "&$H8&" ")))+((tblRules[Test]<>"Word")*ISNUMBER(SEARCH(tblRules[Pattern],$H8))))))>0))*1E+9+ROW(tblRules[Pattern])))-ROW(tblRules[[#Headers],[Pattern]])),"Uncategorized")) | L8: =IF($C8="","",IFERROR(INDEX(tblCategories[Group],MATCH($K8,tblCategories[Category],0)),"Other")) | M8: =IF($C8="","",IFERROR(INDEX(tblCategories[Type],MATCH($K8,tblCategories[Category],0)),IF($J8>0,"Income","Expense"))) | N8: =IF($C8="","",IFERROR(INDEX(tblCategories[Essential],MATCH($K8,tblCategories[Category],0)),"No")) | O8: =IF($C8="","",IFERROR(INDEX(tblCategories[Tax Tag],MATCH($K8,tblCategories[Category],0)),"")) | P8: =IF($C8="","",IF($G8=PersonA,1,IF($G8=PersonB,0,IFERROR(INDEX(tblCategories[Joint Split A],MATCH($K8,tblCategories[Category],0)),DefaultSplitA)))) | Q8: =IF($C8="","",ROUND($J8*N($P8),2)) | R8: =IF($C8="","",ROUND($J8-N($Q8),2)) | U8: sample-data | V8: SAMPLE | W8: 45F839FC | X8: =IF($C8="","",IFERROR(IF(_xlfn.ISFORMULA($K8),"Rule","Manual"),"")) | Y8: =IF($C8="","",IF(ReportView=PersonA,N($Q8),IF(ReportView=PersonB,N($R8),$J8)))
B9: =IF($C9="","","T"&TEXT(ROW()-ROW(tblTxn[[#Headers],[Txn ID]]),"000000")) | C9: 46084 | D9: =IF($C9="","",TEXT($C9,"yyyy-mm")) | E9: BMO Joint Chequing | F9: =IF($C9="","",IFERROR(INDEX(tblAccounts[Owner],MATCH($E9,tblAccounts[Account],0)),"Joint")) | G9: =IF($C9="","",IF(HouseholdMode="Couple",IFERROR(IF(INDEX(tblCategories[Default Owner],MATCH($K9,tblCategories[Category],0))="",$F9,INDEX(tblCategories[Default Owner],MATCH($K9,tblCategories[Category],0))),$F9),$F9)) | H9: GOODLIFE CLUBS PREAUTHORIZED DEBIT | I9: =IF($H9="","",$H9) | J9: -54.22 | K9: =IF($H9="","",IFERROR(INDEX(tblRules[Category],SUMPRODUCT(MIN((1-((tblRules[Enabled]<>"No")*(tblRules[Pattern]<>"")*(tblRules[Category]<>"")*((tblRules[Flow]="Any")+(tblRules[Flow]="")+((tblRules[Flow]="Money out")*($J9<0))+((tblRules[Flow]="Money in")*($J9>0)))*(((tblRules[Look In]="Account")*ISNUMBER(SEARCH(tblRules[Pattern],$E9)))+((tblRules[Look In]<>"Account")*(((tblRules[Test]="Word")*ISNUMBER(SEARCH(" "&tblRules[Pattern]&" "," "&$H9&" ")))+((tblRules[Test]<>"Word")*ISNUMBER(SEARCH(tblRules[Pattern],$H9))))))>0))*1E+9+ROW(tblRules[Pattern])))-ROW(tblRules[[#Headers],[Pattern]])),"Uncategorized")) | L9: =IF($C9="","",IFERROR(INDEX(tblCategories[Group],MATCH($K9,tblCategories[Category],0)),"Other")) | M9: =IF($C9="","",IFERROR(INDEX(tblCategories[Type],MATCH($K9,tblCategories[Category],0)),IF($J9>0,"Income","Expense"))) | N9: =IF($C9="","",IFERROR(INDEX(tblCategories[Essential],MATCH($K9,tblCategories[Category],0)),"No")) | O9: =IF($C9="","",IFERROR(INDEX(tblCategories[Tax Tag],MATCH($K9,tblCategories[Category],0)),"")) | P9: =IF($C9="","",IF($G9=PersonA,1,IF($G9=PersonB,0,IFERROR(INDEX(tblCategories[Joint Split A],MATCH($K9,tblCategories[Category],0)),DefaultSplitA)))) | Q9: =IF($C9="","",ROUND($J9*N($P9),2)) | R9: =IF($C9="","",ROUND($J9-N($Q9),2)) | U9: sample-data | V9: SAMPLE | W9: B1B6FD37 | X9: =IF($C9="","",IFERROR(IF(_xlfn.ISFORMULA($K9),"Rule","Manual"),"")) | Y9: =IF($C9="","",IF(ReportView=PersonA,N($Q9),IF(ReportView=PersonB,N($R9),$J9)))
B10: =IF($C10="","","T"&TEXT(ROW()-ROW(tblTxn[[#Headers],[Txn ID]]),"000000")) | C10: 46084 | D10: =IF($C10="","",TEXT($C10,"yyyy-mm")) | E10: Tangerine Chequing (Sam) | F10: =IF($C10="","",IFERROR(INDEX(tblAccounts[Owner],MATCH($E10,tblAccounts[Account],0)),"Joint")) | G10: =IF($C10="","",IF(HouseholdMode="Couple",IFERROR(IF(INDEX(tblCategories[Default Owner],MATCH($K10,tblCategories[Category],0))="",$F10,INDEX(tblCategories[Default Owner],MATCH($K10,tblCategories[Category],0))),$F10),$F10)) | H10: IDP PURCHASE - 6527 LCBO/RAO #4079 TORONTO ON | I10: =IF($H10="","",$H10) | J10: -28.27 | K10: =IF($H10="","",IFERROR(INDEX(tblRules[Category],SUMPRODUCT(MIN((1-((tblRules[Enabled]<>"No")*(tblRules[Pattern]<>"")*(tblRules[Category]<>"")*((tblRules[Flow]="Any")+(tblRules[Flow]="")+((tblRules[Flow]="Money out")*($J10<0))+((tblRules[Flow]="Money in")*($J10>0)))*(((tblRules[Look In]="Account")*ISNUMBER(SEARCH(tblRules[Pattern],$E10)))+((tblRules[Look In]<>"Account")*(((tblRules[Test]="Word")*ISNUMBER(SEARCH(" "&tblRules[Pattern]&" "," "&$H10&" ")))+((tblRules[Test]<>"Word")*ISNUMBER(SEARCH(tblRules[Pattern],$H10))))))>0))*1E+9+ROW(tblRules[Pattern])))-ROW(tblRules[[#Headers],[Pattern]])),"Uncategorized")) | L10: =IF($C10="","",IFERROR(INDEX(tblCategories[Group],MATCH($K10,tblCategories[Category],0)),"Other")) | M10: =IF($C10="","",IFERROR(INDEX(tblCategories[Type],MATCH($K10,tblCategories[Category],0)),IF($J10>0,"Income","Expense"))) | N10: =IF($C10="","",IFERROR(INDEX(tblCategories[Essential],MATCH($K10,tblCategories[Category],0)),"No")) | O10: =IF($C10="","",IFERROR(INDEX(tblCategories[Tax Tag],MATCH($K10,tblCategories[Category],0)),"")) | P10: =IF($C10="","",IF($G10=PersonA,1,IF($G10=PersonB,0,IFERROR(INDEX(tblCategories[Joint Split A],MATCH($K10,tblCategories[Category],0)),DefaultSplitA)))) | Q10: =IF($C10="","",ROUND($J10*N($P10),2)) | R10: =IF($C10="","",ROUND($J10-N($Q10),2)) | U10: sample-data | V10: SAMPLE | W10: 91FBDF2B | X10: =IF($C10="","",IFERROR(IF(_xlfn.ISFORMULA($K10),"Rule","Manual"),"")) | Y10: =IF($C10="","",IF(ReportView=PersonA,N($Q10),IF(ReportView=PersonB,N($R10),$J10)))
B11: =IF($C11="","","T"&TEXT(ROW()-ROW(tblTxn[[#Headers],[Txn ID]]),"000000")) | C11: 46086 | D11: =IF($C11="","",TEXT($C11,"yyyy-mm")) | E11: Amex Cobalt (Joint) | F11: =IF($C11="","",IFERROR(INDEX(tblAccounts[Owner],MATCH($E11,tblAccounts[Account],0)),"Joint")) | G11: =IF($C11="","",IF(HouseholdMode="Couple",IFERROR(IF(INDEX(tblCategories[Default Owner],MATCH($K11,tblCategories[Category],0))="",$F11,INDEX(tblCategories[Default Owner],MATCH($K11,tblCategories[Category],0))),$F11),$F11)) | H11: IDP PURCHASE - 8060 TIM HORTONS #3324 TORONTO ON | I11: =IF($H11="","",$H11) | J11: -5.8 | K11: =IF($H11="","",IFERROR(INDEX(tblRules[Category],SUMPRODUCT(MIN((1-((tblRules[Enabled]<>"No")*(tblRules[Pattern]<>"")*(tblRules[Category]<>"")*((tblRules[Flow]="Any")+(tblRules[Flow]="")+((tblRules[Flow]="Money out")*($J11<0))+((tblRules[Flow]="Money in")*($J11>0)))*(((tblRules[Look In]="Account")*ISNUMBER(SEARCH(tblRules[Pattern],$E11)))+((tblRules[Look In]<>"Account")*(((tblRules[Test]="Word")*ISNUMBER(SEARCH(" "&tblRules[Pattern]&" "," "&$H11&" ")))+((tblRules[Test]<>"Word")*ISNUMBER(SEARCH(tblRules[Pattern],$H11))))))>0))*1E+9+ROW(tblRules[Pattern])))-ROW(tblRules[[#Headers],[Pattern]])),"Uncategorized")) | L11: =IF($C11="","",IFERROR(INDEX(tblCategories[Group],MATCH($K11,tblCategories[Category],0)),"Other")) | M11: =IF($C11="","",IFERROR(INDEX(tblCategories[Type],MATCH($K11,tblCategories[Category],0)),IF($J11>0,"Income","Expense"))) | N11: =IF($C11="","",IFERROR(INDEX(tblCategories[Essential],MATCH($K11,tblCategories[Category],0)),"No")) | O11: =IF($C11="","",IFERROR(INDEX(tblCategories[Tax Tag],MATCH($K11,tblCategories[Category],0)),"")) | P11: =IF($C11="","",IF($G11=PersonA,1,IF($G11=PersonB,0,IFERROR(INDEX(tblCategories[Joint Split A],MATCH($K11,tblCategories[Category],0)),DefaultSplitA)))) | Q11: =IF($C11="","",ROUND($J11*N($P11),2)) | R11: =IF($C11="","",ROUND($J11-N($Q11),2)) | U11: sample-data | V11: SAMPLE | W11: 76E83383 | X11: =IF($C11="","",IFERROR(IF(_xlfn.ISFORMULA($K11),"Rule","Manual"),"")) | Y11: =IF($C11="","",IF(ReportView=PersonA,N($Q11),IF(ReportView=PersonB,N($R11),$J11)))
B12: =IF($C12="","","T"&TEXT(ROW()-ROW(tblTxn[[#Headers],[Txn ID]]),"000000")) | C12: 46086 | D12: =IF($C12="","",TEXT($C12,"yyyy-mm")) | E12: BMO Joint Chequing | F12: =IF($C12="","",IFERROR(INDEX(tblAccounts[Owner],MATCH($E12,tblAccounts[Account],0)),"Joint")) | G12: =IF($C12="","",IF(HouseholdMode="Couple",IFERROR(IF(INDEX(tblCategories[Default Owner],MATCH($K12,tblCategories[Category],0))="",$F12,INDEX(tblCategories[Default Owner],MATCH($K12,tblCategories[Category],0))),$F12),$F12)) | H12: BELAIRDIRECT INSURANCE PREAUTHORIZED DEBIT | I12: =IF($H12="","",$H12) | J12: -168 | K12: =IF($H12="","",IFERROR(INDEX(tblRules[Category],SUMPRODUCT(MIN((1-((tblRules[Enabled]<>"No")*(tblRules[Pattern]<>"")*(tblRules[Category]<>"")*((tblRules[Flow]="Any")+(tblRules[Flow]="")+((tblRules[Flow]="Money out")*($J12<0))+((tblRules[Flow]="Money in")*($J12>0)))*(((tblRules[Look In]="Account")*ISNUMBER(SEARCH(tblRules[Pattern],$E12)))+((tblRules[Look In]<>"Account")*(((tblRules[Test]="Word")*ISNUMBER(SEARCH(" "&tblRules[Pattern]&" "," "&$H12&" ")))+((tblRules[Test]<>"Word")*ISNUMBER(SEARCH(tblRules[Pattern],$H12))))))>0))*1E+9+ROW(tblRules[Pattern])))-ROW(tblRules[[#Headers],[Pattern]])),"Uncategorized")) | L12: =IF($C12="","",IFERROR(INDEX(tblCategories[Group],MATCH($K12,tblCategories[Category],0)),"Other")) | M12: =IF($C12="","",IFERROR(INDEX(tblCategories[Type],MATCH($K12,tblCategories[Category],0)),IF($J12>0,"Income","Expense"))) | N12: =IF($C12="","",IFERROR(INDEX(tblCategories[Essential],MATCH($K12,tblCategories[Category],0)),"No")) | O12: =IF($C12="","",IFERROR(INDEX(tblCategories[Tax Tag],MATCH($K12,tblCategories[Category],0)),"")) | P12: =IF($C12="","",IF($G12=PersonA,1,IF($G12=PersonB,0,IFERROR(INDEX(tblCategories[Joint Split A],MATCH($K12,tblCategories[Category],0)),DefaultSplitA)))) | Q12: =IF($C12="","",ROUND($J12*N($P12),2)) | R12: =IF($C12="","",ROUND($J12-N($Q12),2)) | U12: sample-data | V12: SAMPLE | W12: 7EA841BF | X12: =IF($C12="","",IFERROR(IF(_xlfn.ISFORMULA($K12),"Rule","Manual"),"")) | Y12: =IF($C12="","",IF(ReportView=PersonA,N($Q12),IF(ReportView=PersonB,N($R12),$J12)))
B13: =IF($C13="","","T"&TEXT(ROW()-ROW(tblTxn[[#Headers],[Txn ID]]),"000000")) | C13: 46086 | D13: =IF($C13="","",TEXT($C13,"yyyy-mm")) | E13: BMO Joint Chequing | F13: =IF($C13="","",IFERROR(INDEX(tblAccounts[Owner],MATCH($E13,tblAccounts[Account],0)),"Joint")) | G13: =IF($C13="","",IF(HouseholdMode="Couple",IFERROR(IF(INDEX(tblCategories[Default Owner],MATCH($K13,tblCategories[Category],0))="",$F13,INDEX(tblCategories[Default Owner],MATCH($K13,tblCategories[Category],0))),$F13),$F13)) | H13: LITTLE MAPLE DAYCARE PREAUTHORIZED DEBIT | I13: =IF($H13="","",$H13) | J13: -880 | K13: =IF($H13="","",IFERROR(INDEX(tblRules[Category],SUMPRODUCT(MIN((1-((tblRules[Enabled]<>"No")*(tblRules[Pattern]<>"")*(tblRules[Category]<>"")*((tblRules[Flow]="Any")+(tblRules[Flow]="")+((tblRules[Flow]="Money out")*($J13<0))+((tblRules[Flow]="Money in")*($J13>0)))*(((tblRules[Look In]="Account")*ISNUMBER(SEARCH(tblRules[Pattern],$E13)))+((tblRules[Look In]<>"Account")*(((tblRules[Test]="Word")*ISNUMBER(SEARCH(" "&tblRules[Pattern]&" "," "&$H13&" ")))+((tblRules[Test]<>"Word")*ISNUMBER(SEARCH(tblRules[Pattern],$H13))))))>0))*1E+9+ROW(tblRules[Pattern])))-ROW(tblRules[[#Headers],[Pattern]])),"Uncategorized")) | L13: =IF($C13="","",IFERROR(INDEX(tblCategories[Group],MATCH($K13,tblCategories[Category],0)),"Other")) | M13: =IF($C13="","",IFERROR(INDEX(tblCategories[Type],MATCH($K13,tblCategories[Category],0)),IF($J13>0,"Income","Expense"))) | N13: =IF($C13="","",IFERROR(INDEX(tblCategories[Essential],MATCH($K13,tblCategories[Category],0)),"No")) | O13: =IF($C13="","",IFERROR(INDEX(tblCategories[Tax Tag],MATCH($K13,tblCategories[Category],0)),"")) | P13: =IF($C13="","",IF($G13=PersonA,1,IF($G13=PersonB,0,IFERROR(INDEX(tblCategories[Joint Split A],MATCH($K13,tblCategories[Category],0)),DefaultSplitA)))) | Q13: =IF($C13="","",ROUND($J13*N($P13),2)) | R13: =IF($C13="","",ROUND($J13-N($Q13),2)) | U13: sample-data | V13: SAMPLE | W13: 856EE728 | X13: =IF($C13="","",IFERROR(IF(_xlfn.ISFORMULA($K13),"Rule","Manual"),"")) | Y13: =IF($C13="","",IF(ReportView=PersonA,N($Q13),IF(ReportView=PersonB,N($R13),$J13)))
B14: =IF($C14="","","T"&TEXT(ROW()-ROW(tblTxn[[#Headers],[Txn ID]]),"000000")) | C14: 46087 | D14: =IF($C14="","",TEXT($C14,"yyyy-mm")) | E14: Amex Cobalt (Joint) | F14: =IF($C14="","",IFERROR(INDEX(tblAccounts[Owner],MATCH($E14,tblAccounts[Account],0)),"Joint")) | G14: =IF($C14="","",IF(HouseholdMode="Couple",IFERROR(IF(INDEX(tblCategories[Default Owner],MATCH($K14,tblCategories[Category],0))="",$F14,INDEX(tblCategories[Default Owner],MATCH($K14,tblCategories[Category],0))),$F14),$F14)) | H14: IDP PURCHASE - 5260 SWISS CHALET #1631 ON | I14: =IF($H14="","",$H14) | J14: -56.99 | K14: =IF($H14="","",IFERROR(INDEX(tblRules[Category],SUMPRODUCT(MIN((1-((tblRules[Enabled]<>"No")*(tblRules[Pattern]<>"")*(tblRules[Category]<>"")*((tblRules[Flow]="Any")+(tblRules[Flow]="")+((tblRules[Flow]="Money out")*($J14<0))+((tblRules[Flow]="Money in")*($J14>0)))*(((tblRules[Look In]="Account")*ISNUMBER(SEARCH(tblRules[Pattern],$E14)))+((tblRules[Look In]<>"Account")*(((tblRules[Test]="Word")*ISNUMBER(SEARCH(" "&tblRules[Pattern]&" "," "&$H14&" ")))+((tblRules[Test]<>"Word")*ISNUMBER(SEARCH(tblRules[Pattern],$H14))))))>0))*1E+9+ROW(tblRules[Pattern])))-ROW(tblRules[[#Headers],[Pattern]])),"Uncategorized")) | L14: =IF($C14="","",IFERROR(INDEX(tblCategories[Group],MATCH($K14,tblCategories[Category],0)),"Other")) | M14: =IF($C14="","",IFERROR(INDEX(tblCategories[Type],MATCH($K14,tblCategories[Category],0)),IF($J14>0,"Income","Expense"))) | N14: =IF($C14="","",IFERROR(INDEX(tblCategories[Essential],MATCH($K14,tblCategories[Category],0)),"No")) | O14: =IF($C14="","",IFERROR(INDEX(tblCategories[Tax Tag],MATCH($K14,tblCategories[Category],0)),"")) | P14: =IF($C14="","",IF($G14=PersonA,1,IF($G14=PersonB,0,IFERROR(INDEX(tblCategories[Joint Split A],MATCH($K14,tblCategories[Category],0)),DefaultSplitA)))) | Q14: =IF($C14="","",ROUND($J14*N($P14),2)) | R14: =IF($C14="","",ROUND($J14-N($Q14),2)) | U14: sample-data | V14: SAMPLE | W14: 573803B2 | X14: =IF($C14="","",IFERROR(IF(_xlfn.ISFORMULA($K14),"Rule","Manual"),"")) | Y14: =IF($C14="","",IF(ReportView=PersonA,N($Q14),IF(ReportView=PersonB,N($R14),$J14)))
B15: =IF($C15="","","T"&TEXT(ROW()-ROW(tblTxn[[#Headers],[Txn ID]]),"000000")) | C15: 46087 | D15: =IF($C15="","",TEXT($C15,"yyyy-mm")) | E15: BMO Joint Chequing | F15: =IF($C15="","",IFERROR(INDEX(tblAccounts[Owner],MATCH($E15,tblAccounts[Account],0)),"Joint")) | G15: =IF($C15="","",IF(HouseholdMode="Couple",IFERROR(IF(INDEX(tblCategories[Default Owner],MATCH($K15,tblCategories[Category],0))="",$F15,INDEX(tblCategories[Default Owner],MATCH($K15,tblCategories[Category],0))),$F15),$F15)) | H15: SUN LIFE ASSURANCE MISC PAYMENT | I15: =IF($H15="","",$H15) | J15: -74.5 | K15: =IF($H15="","",IFERROR(INDEX(tblRules[Category],SUMPRODUCT(MIN((1-((tblRules[Enabled]<>"No")*(tblRules[Pattern]<>"")*(tblRules[Category]<>"")*((tblRules[Flow]="Any")+(tblRules[Flow]="")+((tblRules[Flow]="Money out")*($J15<0))+((tblRules[Flow]="Money in")*($J15>0)))*(((tblRules[Look In]="Account")*ISNUMBER(SEARCH(tblRules[Pattern],$E15)))+((tblRules[Look In]<>"Account")*(((tblRules[Test]="Word")*ISNUMBER(SEARCH(" "&tblRules[Pattern]&" "," "&$H15&" ")))+((tblRules[Test]<>"Word")*ISNUMBER(SEARCH(tblRules[Pattern],$H15))))))>0))*1E+9+ROW(tblRules[Pattern])))-ROW(tblRules[[#Headers],[Pattern]])),"Uncategorized")) | L15: =IF($C15="","",IFERROR(INDEX(tblCategories[Group],MATCH($K15,tblCategories[Category],0)),"Other")) | M15: =IF($C15="","",IFERROR(INDEX(tblCategories[Type],MATCH($K15,tblCategories[Category],0)),IF($J15>0,"Income","Expense"))) | N15: =IF($C15="","",IFERROR(INDEX(tblCategories[Essential],MATCH($K15,tblCategories[Category],0)),"No")) | O15: =IF($C15="","",IFERROR(INDEX(tblCategories[Tax Tag],MATCH($K15,tblCategories[Category],0)),"")) | P15: =IF($C15="","",IF($G15=PersonA,1,IF($G15=PersonB,0,IFERROR(INDEX(tblCategories[Joint Split A],MATCH($K15,tblCategories[Category],0)),DefaultSplitA)))) | Q15: =IF($C15="","",ROUND($J15*N($P15),2)) | R15: =IF($C15="","",ROUND($J15-N($Q15),2)) | U15: sample-data | V15: SAMPLE | W15: 7B77744A | X15: =IF($C15="","",IFERROR(IF(_xlfn.ISFORMULA($K15),"Rule","Manual"),"")) | Y15: =IF($C15="","",IF(ReportView=PersonA,N($Q15),IF(ReportView=PersonB,N($R15),$J15)))
B16: =IF($C16="","","T"&TEXT(ROW()-ROW(tblTxn[[#Headers],[Txn ID]]),"000000")) | C16: 46088 | D16: =IF($C16="","",TEXT($C16,"yyyy-mm")) | E16: Amex Cobalt (Joint) | F16: =IF($C16="","",IFERROR(INDEX(tblAccounts[Owner],MATCH($E16,tblAccounts[Account],0)),"Joint")) | G16: =IF($C16="","",IF(HouseholdMode="Couple",IFERROR(IF(INDEX(tblCategories[Default Owner],MATCH($K16,tblCategories[Category],0))="",$F16,INDEX(tblCategories[Default Owner],MATCH($K16,tblCategories[Category],0))),$F16),$F16)) | H16: IDP PURCHASE - 5650 TIM HORTONS #1246 TORONTO ON | I16: =IF($H16="","",$H16) | J16: -4.17 | K16: =IF($H16="","",IFERROR(INDEX(tblRules[Category],SUMPRODUCT(MIN((1-((tblRules[Enabled]<>"No")*(tblRules[Pattern]<>"")*(tblRules[Category]<>"")*((tblRules[Flow]="Any")+(tblRules[Flow]="")+((tblRules[Flow]="Money out")*($J16<0))+((tblRules[Flow]="Money in")*($J16>0)))*(((tblRules[Look In]="Account")*ISNUMBER(SEARCH(tblRules[Pattern],$E16)))+((tblRules[Look In]<>"Account")*(((tblRules[Test]="Word")*ISNUMBER(SEARCH(" "&tblRules[Pattern]&" "," "&$H16&" ")))+((tblRules[Test]<>"Word")*ISNUMBER(SEARCH(tblRules[Pattern],$H16))))))>0))*1E+9+ROW(tblRules[Pattern])))-ROW(tblRules[[#Headers],[Pattern]])),"Uncategorized")) | L16: =IF($C16="","",IFERROR(INDEX(tblCategories[Group],MATCH($K16,tblCategories[Category],0)),"Other")) | M16: =IF($C16="","",IFERROR(INDEX(tblCategories[Type],MATCH($K16,tblCategories[Category],0)),IF($J16>0,"Income","Expense"))) | N16: =IF($C16="","",IFERROR(INDEX(tblCategories[Essential],MATCH($K16,tblCategories[Category],0)),"No")) | O16: =IF($C16="","",IFERROR(INDEX(tblCategories[Tax Tag],MATCH($K16,tblCategories[Category],0)),"")) | P16: =IF($C16="","",IF($G16=PersonA,1,IF($G16=PersonB,0,IFERROR(INDEX(tblCategories[Joint Split A],MATCH($K16,tblCategories[Category],0)),DefaultSplitA)))) | Q16: =IF($C16="","",ROUND($J16*N($P16),2)) | R16: =IF($C16="","",ROUND($J16-N($Q16),2)) | U16: sample-data | V16: SAMPLE | W16: 003ECA6D | X16: =IF($C16="","",IFERROR(IF(_xlfn.ISFORMULA($K16),"Rule","Manual"),"")) | Y16: =IF($C16="","",IF(ReportView=PersonA,N($Q16),IF(ReportView=PersonB,N($R16),$J16)))
B17: =IF($C17="","","T"&TEXT(ROW()-ROW(tblTxn[[#Headers],[Txn ID]]),"000000")) | C17: 46089 | D17: =IF($C17="","",TEXT($C17,"yyyy-mm")) | E17: BMO Joint Chequing | F17: =IF($C17="","",IFERROR(INDEX(tblAccounts[Owner],MATCH($E17,tblAccounts[Account],0)),"Joint")) | G17: =IF($C17="","",IF(HouseholdMode="Couple",IFERROR(IF(INDEX(tblCategories[Default Owner],MATCH($K17,tblCategories[Category],0))="",$F17,INDEX(tblCategories[Default Owner],MATCH($K17,tblCategories[Category],0))),$F17),$F17)) | H17: TORONTO HYDRO BILL PAYMENT | I17: =IF($H17="","",$H17) | J17: -97.76 | K17: =IF($H17="","",IFERROR(INDEX(tblRules[Category],SUMPRODUCT(MIN((1-((tblRules[Enabled]<>"No")*(tblRules[Pattern]<>"")*(tblRules[Category]<>"")*((tblRules[Flow]="Any")+(tblRules[Flow]="")+((tblRules[Flow]="Money out")*($J17<0))+((tblRules[Flow]="Money in")*($J17>0)))*(((tblRules[Look In]="Account")*ISNUMBER(SEARCH(tblRules[Pattern],$E17)))+((tblRules[Look In]<>"Account")*(((tblRules[Test]="Word")*ISNUMBER(SEARCH(" "&tblRules[Pattern]&" "," "&$H17&" ")))+((tblRules[Test]<>"Word")*ISNUMBER(SEARCH(tblRules[Pattern],$H17))))))>0))*1E+9+ROW(tblRules[Pattern])))-ROW(tblRules[[#Headers],[Pattern]])),"Uncategorized")) | L17: =IF($C17="","",IFERROR(INDEX(tblCategories[Group],MATCH($K17,tblCategories[Category],0)),"Other")) | M17: =IF($C17="","",IFERROR(INDEX(tblCategories[Type],MATCH($K17,tblCategories[Category],0)),IF($J17>0,"Income","Expense"))) | N17: =IF($C17="","",IFERROR(INDEX(tblCategories[Essential],MATCH($K17,tblCategories[Category],0)),"No")) | O17: =IF($C17="","",IFERROR(INDEX(tblCategories[Tax Tag],MATCH($K17,tblCategories[Category],0)),"")) | P17: =IF($C17="","",IF($G17=PersonA,1,IF($G17=PersonB,0,IFERROR(INDEX(tblCategories[Joint Split A],MATCH($K17,tblCategories[Category],0)),DefaultSplitA)))) | Q17: =IF($C17="","",ROUND($J17*N($P17),2)) | R17: =IF($C17="","",ROUND($J17-N($Q17),2)) | U17: sample-data | V17: SAMPLE | W17: 5C2C6966 | X17: =IF($C17="","",IFERROR(IF(_xlfn.ISFORMULA($K17),"Rule","Manual"),"")) | Y17: =IF($C17="","",IF(ReportView=PersonA,N($Q17),IF(ReportView=PersonB,N($R17),$J17)))
B18: =IF($C18="","","T"&TEXT(ROW()-ROW(tblTxn[[#Headers],[Txn ID]]),"000000")) | C18: 46090 | D18: =IF($C18="","",TEXT($C18,"yyyy-mm")) | E18: Amex Cobalt (Joint) | F18: =IF($C18="","",IFERROR(INDEX(tblAccounts[Owner],MATCH($E18,tblAccounts[Account],0)),"Joint")) | G18: =IF($C18="","",IF(HouseholdMode="Couple",IFERROR(IF(INDEX(tblCategories[Default Owner],MATCH($K18,tblCategories[Category],0))="",$F18,INDEX(tblCategories[Default Owner],MATCH($K18,tblCategories[Category],0))),$F18),$F18)) | H18: IDP PURCHASE - 5119 WINNERS #3424 ON | I18: =IF($H18="","",$H18) | J18: -48.55 | K18: =IF($H18="","",IFERROR(INDEX(tblRules[Category],SUMPRODUCT(MIN((1-((tblRules[Enabled]<>"No")*(tblRules[Pattern]<>"")*(tblRules[Category]<>"")*((tblRules[Flow]="Any")+(tblRules[Flow]="")+((tblRules[Flow]="Money out")*($J18<0))+((tblRules[Flow]="Money in")*($J18>0)))*(((tblRules[Look In]="Account")*ISNUMBER(SEARCH(tblRules[Pattern],$E18)))+((tblRules[Look In]<>"Account")*(((tblRules[Test]="Word")*ISNUMBER(SEARCH(" "&tblRules[Pattern]&" "," "&$H18&" ")))+((tblRules[Test]<>"Word")*ISNUMBER(SEARCH(tblRules[Pattern],$H18))))))>0))*1E+9+ROW(tblRules[Pattern])))-ROW(tblRules[[#Headers],[Pattern]])),"Uncategorized")) | L18: =IF($C18="","",IFERROR(INDEX(tblCategories[Group],MATCH($K18,tblCategories[Category],0)),"Other")) | M18: =IF($C18="","",IFERROR(INDEX(tblCategories[Type],MATCH($K18,tblCategories[Category],0)),IF($J18>0,"Income","Expense"))) | N18: =IF($C18="","",IFERROR(INDEX(tblCategories[Essential],MATCH($K18,tblCategories[Category],0)),"No")) | O18: =IF($C18="","",IFERROR(INDEX(tblCategories[Tax Tag],MATCH($K18,tblCategories[Category],0)),"")) | P18: =IF($C18="","",IF($G18=PersonA,1,IF($G18=PersonB,0,IFERROR(INDEX(tblCategories[Joint Split A],MATCH($K18,tblCategories[Category],0)),DefaultSplitA)))) | Q18: =IF($C18="","",ROUND($J18*N($P18),2)) | R18: =IF($C18="","",ROUND($J18-N($Q18),2)) | U18: sample-data | V18: SAMPLE | W18: 44D69BE1 | X18: =IF($C18="","",IFERROR(IF(_xlfn.ISFORMULA($K18),"Rule","Manual"),"")) | Y18: =IF($C18="","",IF(ReportView=PersonA,N($Q18),IF(ReportView=PersonB,N($R18),$J18)))
... B330: =IF($C330="","","T"&TEXT(ROW()-ROW(tblTxn[[#Headers],[Txn ID]]),"000000")) | C330: 46265 | D330: =IF($C330="","",TEXT($C330,"yyyy-mm")) | E330: RBC Chequing (Alex) | F330: =IF($C330="","",IFERROR(INDEX(tblAccounts[Owner],MATCH($E330,tblAccounts[Account],0)),"Joint")) | G330: =IF($C330="","",IF(HouseholdMode="Couple",IFERROR(IF(INDEX(tblCategories[Default Owner],MATCH($K330,tblCategories[Category],0))="",$F330,INDEX(tblCategories[Default Owner],MATCH($K330,tblCategories[Category],0))),$F330),$F330)) | H330: IDP PURCHASE - 6285 TIM HORTONS #3283 TORONTO ON | I330: =IF($H330="","",$H330) | J330: -10.53 | K330: =IF($H330="","",IFERROR(INDEX(tblRules[Category],SUMPRODUCT(MIN((1-((tblRules[Enabled]<>"No")*(tblRules[Pattern]<>"")*(tblRules[Category]<>"")*((tblRules[Flow]="Any")+(tblRules[Flow]="")+((tblRules[Flow]="Money out")*($J330<0))+((tblRules[Flow]="Money in")*($J330>0)))*(((tblRules[Look In]="Account")*ISNUMBER(SEARCH(tblRules[Pattern],$E330)))+((tblRules[Look In]<>"Account")*(((tblRules[Test]="Word")*ISNUMBER(SEARCH(" "&tblRules[Pattern]&" "," "&$H330&" ")))+((tblRules[Test]<>"Word")*ISNUMBER(SEARCH(tblRules[Pattern],$H330))))))>0))*1E+9+ROW(tblRules[Pattern])))-ROW(tblRules[[#Headers],[Pattern]])),"Uncategorized")) | L330: =IF($C330="","",IFERROR(INDEX(tblCategories[Group],MATCH($K330,tblCategories[Category],0)),"Other")) | M330: =IF($C330="","",IFERROR(INDEX(tblCategories[Type],MATCH($K330,tblCategories[Category],0)),IF($J330>0,"Income","Expense"))) | N330: =IF($C330="","",IFERROR(INDEX(tblCategories[Essential],MATCH($K330,tblCategories[Category],0)),"No")) | O330: =IF($C330="","",IFERROR(INDEX(tblCategories[Tax Tag],MATCH($K330,tblCategories[Category],0)),"")) | P330: =IF($C330="","",IF($G330=PersonA,1,IF($G330=PersonB,0,IFERROR(INDEX(tblCategories[Joint Split A],MATCH($K330,tblCategories[Category],0)),DefaultSplitA)))) | Q330: =IF($C330="","",ROUND($J330*N($P330),2)) | R330: =IF($C330="","",ROUND($J330-N($Q330),2)) | U330: sample-data | V330: SAMPLE | W330: D9DD2819 | X330: =IF($C330="","",IFERROR(IF(_xlfn.ISFORMULA($K330),"Rule","Manual"),"")) | Y330: =IF($C330="","",IF(ReportView=PersonA,N($Q330),IF(ReportView=PersonB,N($R330),$J330)))
B331: =IF($C331="","","T"&TEXT(ROW()-ROW(tblTxn[[#Headers],[Txn ID]]),"000000")) | D331: =IF($C331="","",TEXT($C331,"yyyy-mm")) | F331: =IF($C331="","",IFERROR(INDEX(tblAccounts[Owner],MATCH($E331,tblAccounts[Account],0)),"Joint")) | G331: =IF($C331="","",IF(HouseholdMode="Couple",IFERROR(IF(INDEX(tblCategories[Default Owner],MATCH($K331,tblCategories[Category],0))="",$F331,INDEX(tblCategories[Default Owner],MATCH($K331,tblCategories[Category],0))),$F331),$F331)) | I331: =IF($H331="","",$H331) | K331: =IF($H331="","",IFERROR(INDEX(tblRules[Category],SUMPRODUCT(MIN((1-((tblRules[Enabled]<>"No")*(tblRules[Pattern]<>"")*(tblRules[Category]<>"")*((tblRules[Flow]="Any")+(tblRules[Flow]="")+((tblRules[Flow]="Money out")*($J331<0))+((tblRules[Flow]="Money in")*($J331>0)))*(((tblRules[Look In]="Account")*ISNUMBER(SEARCH(tblRules[Pattern],$E331)))+((tblRules[Look In]<>"Account")*(((tblRules[Test]="Word")*ISNUMBER(SEARCH(" "&tblRules[Pattern]&" "," "&$H331&" ")))+((tblRules[Test]<>"Word")*ISNUMBER(SEARCH(tblRules[Pattern],$H331))))))>0))*1E+9+ROW(tblRules[Pattern])))-ROW(tblRules[[#Headers],[Pattern]])),"Uncategorized")) | L331: =IF($C331="","",IFERROR(INDEX(tblCategories[Group],MATCH($K331,tblCategories[Category],0)),"Other")) | M331: =IF($C331="","",IFERROR(INDEX(tblCategories[Type],MATCH($K331,tblCategories[Category],0)),IF($J331>0,"Income","Expense"))) | N331: =IF($C331="","",IFERROR(INDEX(tblCategories[Essential],MATCH($K331,tblCategories[Category],0)),"No")) | O331: =IF($C331="","",IFERROR(INDEX(tblCategories[Tax Tag],MATCH($K331,tblCategories[Category],0)),"")) | P331: =IF($C331="","",IF($G331=PersonA,1,IF($G331=PersonB,0,IFERROR(INDEX(tblCategories[Joint Split A],MATCH($K331,tblCategories[Category],0)),DefaultSplitA)))) | Q331: =IF($C331="","",ROUND($J331*N($P331),2)) | R331: =IF($C331="","",ROUND($J331-N($Q331),2)) | X331: =IF($C331="","",IFERROR(IF(_xlfn.ISFORMULA($K331),"Rule","Manual"),"")) | Y331: =IF($C331="","",IF(ReportView=PersonA,N($Q331),IF(ReportView=PersonB,N($R331),$J331)))
B332: =IF($C332="","","T"&TEXT(ROW()-ROW(tblTxn[[#Headers],[Txn ID]]),"000000")) | D332: =IF($C332="","",TEXT($C332,"yyyy-mm")) | F332: =IF($C332="","",IFERROR(INDEX(tblAccounts[Owner],MATCH($E332,tblAccounts[Account],0)),"Joint")) | G332: =IF($C332="","",IF(HouseholdMode="Couple",IFERROR(IF(INDEX(tblCategories[Default Owner],MATCH($K332,tblCategories[Category],0))="",$F332,INDEX(tblCategories[Default Owner],MATCH($K332,tblCategories[Category],0))),$F332),$F332)) | I332: =IF($H332="","",$H332) | K332: =IF($H332="","",IFERROR(INDEX(tblRules[Category],SUMPRODUCT(MIN((1-((tblRules[Enabled]<>"No")*(tblRules[Pattern]<>"")*(tblRules[Category]<>"")*((tblRules[Flow]="Any")+(tblRules[Flow]="")+((tblRules[Flow]="Money out")*($J332<0))+((tblRules[Flow]="Money in")*($J332>0)))*(((tblRules[Look In]="Account")*ISNUMBER(SEARCH(tblRules[Pattern],$E332)))+((tblRules[Look In]<>"Account")*(((tblRules[Test]="Word")*ISNUMBER(SEARCH(" "&tblRules[Pattern]&" "," "&$H332&" ")))+((tblRules[Test]<>"Word")*ISNUMBER(SEARCH(tblRules[Pattern],$H332))))))>0))*1E+9+ROW(tblRules[Pattern])))-ROW(tblRules[[#Headers],[Pattern]])),"Uncategorized")) | L332: =IF($C332="","",IFERROR(INDEX(tblCategories[Group],MATCH($K332,tblCategories[Category],0)),"Other")) | M332: =IF($C332="","",IFERROR(INDEX(tblCategories[Type],MATCH($K332,tblCategories[Category],0)),IF($J332>0,"Income","Expense"))) | N332: =IF($C332="","",IFERROR(INDEX(tblCategories[Essential],MATCH($K332,tblCategories[Category],0)),"No")) | O332: =IF($C332="","",IFERROR(INDEX(tblCategories[Tax Tag],MATCH($K332,tblCategories[Category],0)),"")) | P332: =IF($C332="","",IF($G332=PersonA,1,IF($G332=PersonB,0,IFERROR(INDEX(tblCategories[Joint Split A],MATCH($K332,tblCategories[Category],0)),DefaultSplitA)))) | Q332: =IF($C332="","",ROUND($J332*N($P332),2)) | R332: =IF($C332="","",ROUND($J332-N($Q332),2)) | X332: =IF($C332="","",IFERROR(IF(_xlfn.ISFORMULA($K332),"Rule","Manual"),"")) | Y332: =IF($C332="","",IF(ReportView=PersonA,N($Q332),IF(ReportView=PersonB,N($R332),$J332)))
B333: =IF($C333="","","T"&TEXT(ROW()-ROW(tblTxn[[#Headers],[Txn ID]]),"000000")) | D333: =IF($C333="","",TEXT($C333,"yyyy-mm")) | F333: =IF($C333="","",IFERROR(INDEX(tblAccounts[Owner],MATCH($E333,tblAccounts[Account],0)),"Joint")) | G333: =IF($C333="","",IF(HouseholdMode="Couple",IFERROR(IF(INDEX(tblCategories[Default Owner],MATCH($K333,tblCategories[Category],0))="",$F333,INDEX(tblCategories[Default Owner],MATCH($K333,tblCategories[Category],0))),$F333),$F333)) | I333: =IF($H333="","",$H333) | K333: =IF($H333="","",IFERROR(INDEX(tblRules[Category],SUMPRODUCT(MIN((1-((tblRules[Enabled]<>"No")*(tblRules[Pattern]<>"")*(tblRules[Category]<>"")*((tblRules[Flow]="Any")+(tblRules[Flow]="")+((tblRules[Flow]="Money out")*($J333<0))+((tblRules[Flow]="Money in")*($J333>0)))*(((tblRules[Look In]="Account")*ISNUMBER(SEARCH(tblRules[Pattern],$E333)))+((tblRules[Look In]<>"Account")*(((tblRules[Test]="Word")*ISNUMBER(SEARCH(" "&tblRules[Pattern]&" "," "&$H333&" ")))+((tblRules[Test]<>"Word")*ISNUMBER(SEARCH(tblRules[Pattern],$H333))))))>0))*1E+9+ROW(tblRules[Pattern])))-ROW(tblRules[[#Headers],[Pattern]])),"Uncategorized")) | L333: =IF($C333="","",IFERROR(INDEX(tblCategories[Group],MATCH($K333,tblCategories[Category],0)),"Other")) | M333: =IF($C333="","",IFERROR(INDEX(tblCategories[Type],MATCH($K333,tblCategories[Category],0)),IF($J333>0,"Income","Expense"))) | N333: =IF($C333="","",IFERROR(INDEX(tblCategories[Essential],MATCH($K333,tblCategories[Category],0)),"No")) | O333: =IF($C333="","",IFERROR(INDEX(tblCategories[Tax Tag],MATCH($K333,tblCategories[Category],0)),"")) | P333: =IF($C333="","",IF($G333=PersonA,1,IF($G333=PersonB,0,IFERROR(INDEX(tblCategories[Joint Split A],MATCH($K333,tblCategories[Category],0)),DefaultSplitA)))) | Q333: =IF($C333="","",ROUND($J333*N($P333),2)) | R333: =IF($C333="","",ROUND($J333-N($Q333),2)) | X333: =IF($C333="","",IFERROR(IF(_xlfn.ISFORMULA($K333),"Rule","Manual"),"")) | Y333: =IF($C333="","",IF(ReportView=PersonA,N($Q333),IF(ReportView=PersonB,N($R333),$J333)))
B334: =IF($C334="","","T"&TEXT(ROW()-ROW(tblTxn[[#Headers],[Txn ID]]),"000000")) | D334: =IF($C334="","",TEXT($C334,"yyyy-mm")) | F334: =IF($C334="","",IFERROR(INDEX(tblAccounts[Owner],MATCH($E334,tblAccounts[Account],0)),"Joint")) | G334: =IF($C334="","",IF(HouseholdMode="Couple",IFERROR(IF(INDEX(tblCategories[Default Owner],MATCH($K334,tblCategories[Category],0))="",$F334,INDEX(tblCategories[Default Owner],MATCH($K334,tblCategories[Category],0))),$F334),$F334)) | I334: =IF($H334="","",$H334) | K334: =IF($H334="","",IFERROR(INDEX(tblRules[Category],SUMPRODUCT(MIN((1-((tblRules[Enabled]<>"No")*(tblRules[Pattern]<>"")*(tblRules[Category]<>"")*((tblRules[Flow]="Any")+(tblRules[Flow]="")+((tblRules[Flow]="Money out")*($J334<0))+((tblRules[Flow]="Money in")*($J334>0)))*(((tblRules[Look In]="Account")*ISNUMBER(SEARCH(tblRules[Pattern],$E334)))+((tblRules[Look In]<>"Account")*(((tblRules[Test]="Word")*ISNUMBER(SEARCH(" "&tblRules[Pattern]&" "," "&$H334&" ")))+((tblRules[Test]<>"Word")*ISNUMBER(SEARCH(tblRules[Pattern],$H334))))))>0))*1E+9+ROW(tblRules[Pattern])))-ROW(tblRules[[#Headers],[Pattern]])),"Uncategorized")) | L334: =IF($C334="","",IFERROR(INDEX(tblCategories[Group],MATCH($K334,tblCategories[Category],0)),"Other")) | M334: =IF($C334="","",IFERROR(INDEX(tblCategories[Type],MATCH($K334,tblCategories[Category],0)),IF($J334>0,"Income","Expense"))) | N334: =IF($C334="","",IFERROR(INDEX(tblCategories[Essential],MATCH($K334,tblCategories[Category],0)),"No")) | O334: =IF($C334="","",IFERROR(INDEX(tblCategories[Tax Tag],MATCH($K334,tblCategories[Category],0)),"")) | P334: =IF($C334="","",IF($G334=PersonA,1,IF($G334=PersonB,0,IFERROR(INDEX(tblCategories[Joint Split A],MATCH($K334,tblCategories[Category],0)),DefaultSplitA)))) | Q334: =IF($C334="","",ROUND($J334*N($P334),2)) | R334: =IF($C334="","",ROUND($J334-N($Q334),2)) | X334: =IF($C334="","",IFERROR(IF(_xlfn.ISFORMULA($K334),"Rule","Manual"),"")) | Y334: =IF($C334="","",IF(ReportView=PersonA,N($Q334),IF(ReportView=PersonB,N($R334),$J334)))
B335: =IF($C335="","","T"&TEXT(ROW()-ROW(tblTxn[[#Headers],[Txn ID]]),"000000")) | D335: =IF($C335="","",TEXT($C335,"yyyy-mm")) | F335: =IF($C335="","",IFERROR(INDEX(tblAccounts[Owner],MATCH($E335,tblAccounts[Account],0)),"Joint")) | G335: =IF($C335="","",IF(HouseholdMode="Couple",IFERROR(IF(INDEX(tblCategories[Default Owner],MATCH($K335,tblCategories[Category],0))="",$F335,INDEX(tblCategories[Default Owner],MATCH($K335,tblCategories[Category],0))),$F335),$F335)) | I335: =IF($H335="","",$H335) | K335: =IF($H335="","",IFERROR(INDEX(tblRules[Category],SUMPRODUCT(MIN((1-((tblRules[Enabled]<>"No")*(tblRules[Pattern]<>"")*(tblRules[Category]<>"")*((tblRules[Flow]="Any")+(tblRules[Flow]="")+((tblRules[Flow]="Money out")*($J335<0))+((tblRules[Flow]="Money in")*($J335>0)))*(((tblRules[Look In]="Account")*ISNUMBER(SEARCH(tblRules[Pattern],$E335)))+((tblRules[Look In]<>"Account")*(((tblRules[Test]="Word")*ISNUMBER(SEARCH(" "&tblRules[Pattern]&" "," "&$H335&" ")))+((tblRules[Test]<>"Word")*ISNUMBER(SEARCH(tblRules[Pattern],$H335))))))>0))*1E+9+ROW(tblRules[Pattern])))-ROW(tblRules[[#Headers],[Pattern]])),"Uncategorized")) | L335: =IF($C335="","",IFERROR(INDEX(tblCategories[Group],MATCH($K335,tblCategories[Category],0)),"Other")) | M335: =IF($C335="","",IFERROR(INDEX(tblCategories[Type],MATCH($K335,tblCategories[Category],0)),IF($J335>0,"Income","Expense"))) | N335: =IF($C335="","",IFERROR(INDEX(tblCategories[Essential],MATCH($K335,tblCategories[Category],0)),"No")) | O335: =IF($C335="","",IFERROR(INDEX(tblCategories[Tax Tag],MATCH($K335,tblCategories[Category],0)),"")) | P335: =IF($C335="","",IF($G335=PersonA,1,IF($G335=PersonB,0,IFERROR(INDEX(tblCategories[Joint Split A],MATCH($K335,tblCategories[Category],0)),DefaultSplitA)))) | Q335: =IF($C335="","",ROUND($J335*N($P335),2)) | R335: =IF($C335="","",ROUND($J335-N($Q335),2)) | X335: =IF($C335="","",IFERROR(IF(_xlfn.ISFORMULA($K335),"Rule","Manual"),"")) | Y335: =IF($C335="","",IF(ReportView=PersonA,N($Q335),IF(ReportView=PersonB,N($R335),$J335)))
B336: =IF($C336="","","T"&TEXT(ROW()-ROW(tblTxn[[#Headers],[Txn ID]]),"000000")) | D336: =IF($C336="","",TEXT($C336,"yyyy-mm")) | F336: =IF($C336="","",IFERROR(INDEX(tblAccounts[Owner],MATCH($E336,tblAccounts[Account],0)),"Joint")) | G336: =IF($C336="","",IF(HouseholdMode="Couple",IFERROR(IF(INDEX(tblCategories[Default Owner],MATCH($K336,tblCategories[Category],0))="",$F336,INDEX(tblCategories[Default Owner],MATCH($K336,tblCategories[Category],0))),$F336),$F336)) | I336: =IF($H336="","",$H336) | K336: =IF($H336="","",IFERROR(INDEX(tblRules[Category],SUMPRODUCT(MIN((1-((tblRules[Enabled]<>"No")*(tblRules[Pattern]<>"")*(tblRules[Category]<>"")*((tblRules[Flow]="Any")+(tblRules[Flow]="")+((tblRules[Flow]="Money out")*($J336<0))+((tblRules[Flow]="Money in")*($J336>0)))*(((tblRules[Look In]="Account")*ISNUMBER(SEARCH(tblRules[Pattern],$E336)))+((tblRules[Look In]<>"Account")*(((tblRules[Test]="Word")*ISNUMBER(SEARCH(" "&tblRules[Pattern]&" "," "&$H336&" ")))+((tblRules[Test]<>"Word")*ISNUMBER(SEARCH(tblRules[Pattern],$H336))))))>0))*1E+9+ROW(tblRules[Pattern])))-ROW(tblRules[[#Headers],[Pattern]])),"Uncategorized")) | L336: =IF($C336="","",IFERROR(INDEX(tblCategories[Group],MATCH($K336,tblCategories[Category],0)),"Other")) | M336: =IF($C336="","",IFERROR(INDEX(tblCategories[Type],MATCH($K336,tblCategories[Category],0)),IF($J336>0,"Income","Expense"))) | N336: =IF($C336="","",IFERROR(INDEX(tblCategories[Essential],MATCH($K336,tblCategories[Category],0)),"No")) | O336: =IF($C336="","",IFERROR(INDEX(tblCategories[Tax Tag],MATCH($K336,tblCategories[Category],0)),"")) | P336: =IF($C336="","",IF($G336=PersonA,1,IF($G336=PersonB,0,IFERROR(INDEX(tblCategories[Joint Split A],MATCH($K336,tblCategories[Category],0)),DefaultSplitA)))) | Q336: =IF($C336="","",ROUND($J336*N($P336),2)) | R336: =IF($C336="","",ROUND($J336-N($Q336),2)) | X336: =IF($C336="","",IFERROR(IF(_xlfn.ISFORMULA($K336),"Rule","Manual"),"")) | Y336: =IF($C336="","",IF(ReportView=PersonA,N($Q336),IF(ReportView=PersonB,N($R336),$J336)))
B337: =IF($C337="","","T"&TEXT(ROW()-ROW(tblTxn[[#Headers],[Txn ID]]),"000000")) | D337: =IF($C337="","",TEXT($C337,"yyyy-mm")) | F337: =IF($C337="","",IFERROR(INDEX(tblAccounts[Owner],MATCH($E337,tblAccounts[Account],0)),"Joint")) | G337: =IF($C337="","",IF(HouseholdMode="Couple",IFERROR(IF(INDEX(tblCategories[Default Owner],MATCH($K337,tblCategories[Category],0))="",$F337,INDEX(tblCategories[Default Owner],MATCH($K337,tblCategories[Category],0))),$F337),$F337)) | I337: =IF($H337="","",$H337) | K337: =IF($H337="","",IFERROR(INDEX(tblRules[Category],SUMPRODUCT(MIN((1-((tblRules[Enabled]<>"No")*(tblRules[Pattern]<>"")*(tblRules[Category]<>"")*((tblRules[Flow]="Any")+(tblRules[Flow]="")+((tblRules[Flow]="Money out")*($J337<0))+((tblRules[Flow]="Money in")*($J337>0)))*(((tblRules[Look In]="Account")*ISNUMBER(SEARCH(tblRules[Pattern],$E337)))+((tblRules[Look In]<>"Account")*(((tblRules[Test]="Word")*ISNUMBER(SEARCH(" "&tblRules[Pattern]&" "," "&$H337&" ")))+((tblRules[Test]<>"Word")*ISNUMBER(SEARCH(tblRules[Pattern],$H337))))))>0))*1E+9+ROW(tblRules[Pattern])))-ROW(tblRules[[#Headers],[Pattern]])),"Uncategorized")) | L337: =IF($C337="","",IFERROR(INDEX(tblCategories[Group],MATCH($K337,tblCategories[Category],0)),"Other")) | M337: =IF($C337="","",IFERROR(INDEX(tblCategories[Type],MATCH($K337,tblCategories[Category],0)),IF($J337>0,"Income","Expense"))) | N337: =IF($C337="","",IFERROR(INDEX(tblCategories[Essential],MATCH($K337,tblCategories[Category],0)),"No")) | O337: =IF($C337="","",IFERROR(INDEX(tblCategories[Tax Tag],MATCH($K337,tblCategories[Category],0)),"")) | P337: =IF($C337="","",IF($G337=PersonA,1,IF($G337=PersonB,0,IFERROR(INDEX(tblCategories[Joint Split A],MATCH($K337,tblCategories[Category],0)),DefaultSplitA)))) | Q337: =IF($C337="","",ROUND($J337*N($P337),2)) | R337: =IF($C337="","",ROUND($J337-N($Q337),2)) | X337: =IF($C337="","",IFERROR(IF(_xlfn.ISFORMULA($K337),"Rule","Manual"),"")) | Y337: =IF($C337="","",IF(ReportView=PersonA,N($Q337),IF(ReportView=PersonB,N($R337),$J337)))
B338: =IF($C338="","","T"&TEXT(ROW()-ROW(tblTxn[[#Headers],[Txn ID]]),"000000")) | D338: =IF($C338="","",TEXT($C338,"yyyy-mm")) | F338: =IF($C338="","",IFERROR(INDEX(tblAccounts[Owner],MATCH($E338,tblAccounts[Account],0)),"Joint")) | G338: =IF($C338="","",IF(HouseholdMode="Couple",IFERROR(IF(INDEX(tblCategories[Default Owner],MATCH($K338,tblCategories[Category],0))="",$F338,INDEX(tblCategories[Default Owner],MATCH($K338,tblCategories[Category],0))),$F338),$F338)) | I338: =IF($H338="","",$H338) | K338: =IF($H338="","",IFERROR(INDEX(tblRules[Category],SUMPRODUCT(MIN((1-((tblRules[Enabled]<>"No")*(tblRules[Pattern]<>"")*(tblRules[Category]<>"")*((tblRules[Flow]="Any")+(tblRules[Flow]="")+((tblRules[Flow]="Money out")*($J338<0))+((tblRules[Flow]="Money in")*($J338>0)))*(((tblRules[Look In]="Account")*ISNUMBER(SEARCH(tblRules[Pattern],$E338)))+((tblRules[Look In]<>"Account")*(((tblRules[Test]="Word")*ISNUMBER(SEARCH(" "&tblRules[Pattern]&" "," "&$H338&" ")))+((tblRules[Test]<>"Word")*ISNUMBER(SEARCH(tblRules[Pattern],$H338))))))>0))*1E+9+ROW(tblRules[Pattern])))-ROW(tblRules[[#Headers],[Pattern]])),"Uncategorized")) | L338: =IF($C338="","",IFERROR(INDEX(tblCategories[Group],MATCH($K338,tblCategories[Category],0)),"Other")) | M338: =IF($C338="","",IFERROR(INDEX(tblCategories[Type],MATCH($K338,tblCategories[Category],0)),IF($J338>0,"Income","Expense"))) | N338: =IF($C338="","",IFERROR(INDEX(tblCategories[Essential],MATCH($K338,tblCategories[Category],0)),"No")) | O338: =IF($C338="","",IFERROR(INDEX(tblCategories[Tax Tag],MATCH($K338,tblCategories[Category],0)),"")) | P338: =IF($C338="","",IF($G338=PersonA,1,IF($G338=PersonB,0,IFERROR(INDEX(tblCategories[Joint Split A],MATCH($K338,tblCategories[Category],0)),DefaultSplitA)))) | Q338: =IF($C338="","",ROUND($J338*N($P338),2)) | R338: =IF($C338="","",ROUND($J338-N($Q338),2)) | X338: =IF($C338="","",IFERROR(IF(_xlfn.ISFORMULA($K338),"Rule","Manual"),"")) | Y338: =IF($C338="","",IF(ReportView=PersonA,N($Q338),IF(ReportView=PersonB,N($R338),$J338)))
B339: =IF($C339="","","T"&TEXT(ROW()-ROW(tblTxn[[#Headers],[Txn ID]]),"000000")) | D339: =IF($C339="","",TEXT($C339,"yyyy-mm")) | F339: =IF($C339="","",IFERROR(INDEX(tblAccounts[Owner],MATCH($E339,tblAccounts[Account],0)),"Joint")) | G339: =IF($C339="","",IF(HouseholdMode="Couple",IFERROR(IF(INDEX(tblCategories[Default Owner],MATCH($K339,tblCategories[Category],0))="",$F339,INDEX(tblCategories[Default Owner],MATCH($K339,tblCategories[Category],0))),$F339),$F339)) | I339: =IF($H339="","",$H339) | K339: =IF($H339="","",IFERROR(INDEX(tblRules[Category],SUMPRODUCT(MIN((1-((tblRules[Enabled]<>"No")*(tblRules[Pattern]<>"")*(tblRules[Category]<>"")*((tblRules[Flow]="Any")+(tblRules[Flow]="")+((tblRules[Flow]="Money out")*($J339<0))+((tblRules[Flow]="Money in")*($J339>0)))*(((tblRules[Look In]="Account")*ISNUMBER(SEARCH(tblRules[Pattern],$E339)))+((tblRules[Look In]<>"Account")*(((tblRules[Test]="Word")*ISNUMBER(SEARCH(" "&tblRules[Pattern]&" "," "&$H339&" ")))+((tblRules[Test]<>"Word")*ISNUMBER(SEARCH(tblRules[Pattern],$H339))))))>0))*1E+9+ROW(tblRules[Pattern])))-ROW(tblRules[[#Headers],[Pattern]])),"Uncategorized")) | L339: =IF($C339="","",IFERROR(INDEX(tblCategories[Group],MATCH($K339,tblCategories[Category],0)),"Other")) | M339: =IF($C339="","",IFERROR(INDEX(tblCategories[Type],MATCH($K339,tblCategories[Category],0)),IF($J339>0,"Income","Expense"))) | N339: =IF($C339="","",IFERROR(INDEX(tblCategories[Essential],MATCH($K339,tblCategories[Category],0)),"No")) | O339: =IF($C339="","",IFERROR(INDEX(tblCategories[Tax Tag],MATCH($K339,tblCategories[Category],0)),"")) | P339: =IF($C339="","",IF($G339=PersonA,1,IF($G339=PersonB,0,IFERROR(INDEX(tblCategories[Joint Split A],MATCH($K339,tblCategories[Category],0)),DefaultSplitA)))) | Q339: =IF($C339="","",ROUND($J339*N($P339),2)) | R339: =IF($C339="","",ROUND($J339-N($Q339),2)) | X339: =IF($C339="","",IFERROR(IF(_xlfn.ISFORMULA($K339),"Rule","Manual"),"")) | Y339: =IF($C339="","",IF(ReportView=PersonA,N($Q339),IF(ReportView=PersonB,N($R339),$J339)))
B340: =IF($C340="","","T"&TEXT(ROW()-ROW(tblTxn[[#Headers],[Txn ID]]),"000000")) | D340: =IF($C340="","",TEXT($C340,"yyyy-mm")) | F340: =IF($C340="","",IFERROR(INDEX(tblAccounts[Owner],MATCH($E340,tblAccounts[Account],0)),"Joint")) | G340: =IF($C340="","",IF(HouseholdMode="Couple",IFERROR(IF(INDEX(tblCategories[Default Owner],MATCH($K340,tblCategories[Category],0))="",$F340,INDEX(tblCategories[Default Owner],MATCH($K340,tblCategories[Category],0))),$F340),$F340)) | I340: =IF($H340="","",$H340) | K340: =IF($H340="","",IFERROR(INDEX(tblRules[Category],SUMPRODUCT(MIN((1-((tblRules[Enabled]<>"No")*(tblRules[Pattern]<>"")*(tblRules[Category]<>"")*((tblRules[Flow]="Any")+(tblRules[Flow]="")+((tblRules[Flow]="Money out")*($J340<0))+((tblRules[Flow]="Money in")*($J340>0)))*(((tblRules[Look In]="Account")*ISNUMBER(SEARCH(tblRules[Pattern],$E340)))+((tblRules[Look In]<>"Account")*(((tblRules[Test]="Word")*ISNUMBER(SEARCH(" "&tblRules[Pattern]&" "," "&$H340&" ")))+((tblRules[Test]<>"Word")*ISNUMBER(SEARCH(tblRules[Pattern],$H340))))))>0))*1E+9+ROW(tblRules[Pattern])))-ROW(tblRules[[#Headers],[Pattern]])),"Uncategorized")) | L340: =IF($C340="","",IFERROR(INDEX(tblCategories[Group],MATCH($K340,tblCategories[Category],0)),"Other")) | M340: =IF($C340="","",IFERROR(INDEX(tblCategories[Type],MATCH($K340,tblCategories[Category],0)),IF($J340>0,"Income","Expense"))) | N340: =IF($C340="","",IFERROR(INDEX(tblCategories[Essential],MATCH($K340,tblCategories[Category],0)),"No")) | O340: =IF($C340="","",IFERROR(INDEX(tblCategories[Tax Tag],MATCH($K340,tblCategories[Category],0)),"")) | P340: =IF($C340="","",IF($G340=PersonA,1,IF($G340=PersonB,0,IFERROR(INDEX(tblCategories[Joint Split A],MATCH($K340,tblCategories[Category],0)),DefaultSplitA)))) | Q340: =IF($C340="","",ROUND($J340*N($P340),2)) | R340: =IF($C340="","",ROUND($J340-N($Q340),2)) | X340: =IF($C340="","",IFERROR(IF(_xlfn.ISFORMULA($K340),"Rule","Manual"),"")) | Y340: =IF($C340="","",IF(ReportView=PersonA,N($Q340),IF(ReportView=PersonB,N($R340),$J340)))
